<?xml version='1.0' encoding='UTF-8'?>
<robot name="gripper_3f_2j">
  <link name="palm">
    <inertial>
      <origin xyz="0.0 0.0 0.0" rpy="0.0 -0.0 0.0"/>
      <mass value="1.0"/>
      <inertia ixx="1.0" ixy="0.0" ixz="0.0" iyy="1.0" iyz="0.0" izz="1.0"/>
    </inertial>
    <visual>
      <geometry>
        <cylinder radius="0.05" length="0.03"/>
      </geometry>
      <material name="blue"/>
      <origin xyz="0.0 0.0 0.0" rpy="0.0 -0.0 0.0"/>
    </visual>
    <collision>
      <geometry>
        <cylinder radius="0.05" length="0.03"/>
      </geometry>
      <origin xyz="0.0 0.0 0.0" rpy="0.0 0.0 0.0"/>
    </collision>
  </link>
  <link name="f11">
    <inertial>
      <origin xyz="0.0 0.0 0.0" rpy="0.0 -0.0 0.0"/>
      <mass value="1.0"/>
      <inertia ixx="1.0" ixy="0.0" ixz="0.0" iyy="1.0" iyz="0.0" izz="1.0"/>
    </inertial>
    <visual>
      <geometry>
        <cylinder radius="0.014696516101604294" length="0.047548421118199145"/>
      </geometry>
      <material name="green"/>
      <origin xyz="0.0 0.0 0.023774210559099573" rpy="0.0 -0.0 0.0"/>
    </visual>
    <collision>
      <geometry>
        <cylinder radius="0.014696516101604294" length="0.047548421118199145"/>
      </geometry>
      <origin xyz="0.0 0.0 0.025" rpy="0.0 0.0 0.0"/>
    </collision>
  </link>
  <link name="f12">
    <inertial>
      <origin xyz="0.0 0.0 0.0" rpy="0.0 -0.0 0.0"/>
      <mass value="1.0"/>
      <inertia ixx="1.0" ixy="0.0" ixz="0.0" iyy="1.0" iyz="0.0" izz="1.0"/>
    </inertial>
    <visual>
      <geometry>
        <cylinder radius="0.014696516101604294" length="0.08328211028707128"/>
      </geometry>
      <material name="green"/>
      <origin xyz="0.0 0.0 0.04164105514353564" rpy="0.0 -0.0 0.0"/>
    </visual>
    <collision>
      <geometry>
        <cylinder radius="0.014696516101604294" length="0.08328211028707128"/>
      </geometry>
      <origin xyz="0.0 0.0 0.025" rpy="0.0 0.0 0.0"/>
    </collision>
  </link>
  <link name="f21">
    <inertial>
      <origin xyz="0.0 0.0 0.0" rpy="0.0 -0.0 0.0"/>
      <mass value="1.0"/>
      <inertia ixx="1.0" ixy="0.0" ixz="0.0" iyy="1.0" iyz="0.0" izz="1.0"/>
    </inertial>
    <visual>
      <geometry>
        <cylinder radius="0.014696516101604294" length="0.047548421118199145"/>
      </geometry>
      <material name="green"/>
      <origin xyz="0.0 0.0 0.023774210559099573" rpy="0.0 -0.0 0.0"/>
    </visual>
    <collision>
      <geometry>
        <cylinder radius="0.014696516101604294" length="0.047548421118199145"/>
      </geometry>
      <origin xyz="0.0 0.0 0.025" rpy="0.0 0.0 0.0"/>
    </collision>
  </link>
  <link name="f22">
    <inertial>
      <origin xyz="0.0 0.0 0.0" rpy="0.0 -0.0 0.0"/>
      <mass value="1.0"/>
      <inertia ixx="1.0" ixy="0.0" ixz="0.0" iyy="1.0" iyz="0.0" izz="1.0"/>
    </inertial>
    <visual>
      <geometry>
        <cylinder radius="0.014696516101604294" length="0.08328211028707128"/>
      </geometry>
      <material name="green"/>
      <origin xyz="0.0 0.0 0.04164105514353564" rpy="0.0 -0.0 0.0"/>
    </visual>
    <collision>
      <geometry>
        <cylinder radius="0.014696516101604294" length="0.08328211028707128"/>
      </geometry>
      <origin xyz="0.0 0.0 0.025" rpy="0.0 0.0 0.0"/>
    </collision>
  </link>
  <link name="f31">
    <inertial>
      <origin xyz="0.0 0.0 0.0" rpy="0.0 -0.0 0.0"/>
      <mass value="1.0"/>
      <inertia ixx="1.0" ixy="0.0" ixz="0.0" iyy="1.0" iyz="0.0" izz="1.0"/>
    </inertial>
    <visual>
      <geometry>
        <cylinder radius="0.014696516101604294" length="0.047548421118199145"/>
      </geometry>
      <material name="green"/>
      <origin xyz="0.0 0.0 0.023774210559099573" rpy="0.0 -0.0 0.0"/>
    </visual>
    <collision>
      <geometry>
        <cylinder radius="0.014696516101604294" length="0.047548421118199145"/>
      </geometry>
      <origin xyz="0.0 0.0 0.025" rpy="0.0 0.0 0.0"/>
    </collision>
  </link>
  <link name="f32">
    <inertial>
      <origin xyz="0.0 0.0 0.0" rpy="0.0 -0.0 0.0"/>
      <mass value="1.0"/>
      <inertia ixx="1.0" ixy="0.0" ixz="0.0" iyy="1.0" iyz="0.0" izz="1.0"/>
    </inertial>
    <visual>
      <geometry>
        <cylinder radius="0.014696516101604294" length="0.08328211028707128"/>
      </geometry>
      <material name="green"/>
      <origin xyz="0.0 0.0 0.04164105514353564" rpy="0.0 -0.0 0.0"/>
    </visual>
    <collision>
      <geometry>
        <cylinder radius="0.014696516101604294" length="0.08328211028707128"/>
      </geometry>
      <origin xyz="0.0 0.0 0.025" rpy="0.0 0.0 0.0"/>
    </collision>
  </link>
  <link name="f11_base">
    <inertial>
      <origin xyz="0.0 0.0 0.0" rpy="0.0 -0.0 0.0"/>
      <mass value="1.0"/>
      <inertia ixx="1.0" ixy="0.0" ixz="0.0" iyy="1.0" iyz="0.0" izz="1.0"/>
    </inertial>
    <visual>
      <geometry>
        <sphere radius="0.015"/>
      </geometry>
      <origin xyz="0.0 0.0 0.0" rpy="0.0 -0.0 0.0"/>
    </visual>
  </link>
  <link name="f12_slot">
    <inertial>
      <origin xyz="0.0 0.0 0.0" rpy="0.0 -0.0 0.0"/>
      <mass value="1.0"/>
      <inertia ixx="1.0" ixy="0.0" ixz="0.0" iyy="1.0" iyz="0.0" izz="1.0"/>
    </inertial>
    <visual>
      <geometry>
        <sphere radius="0.015"/>
      </geometry>
      <origin xyz="0.0 0.0 0.0" rpy="0.0 -0.0 0.0"/>
    </visual>
  </link>
  <link name="f21_base">
    <inertial>
      <origin xyz="0.0 0.0 0.0" rpy="0.0 -0.0 0.0"/>
      <mass value="1.0"/>
      <inertia ixx="1.0" ixy="0.0" ixz="0.0" iyy="1.0" iyz="0.0" izz="1.0"/>
    </inertial>
    <visual>
      <geometry>
        <sphere radius="0.015"/>
      </geometry>
      <origin xyz="0.0 0.0 0.0" rpy="0.0 -0.0 0.0"/>
    </visual>
  </link>
  <link name="f22_slot">
    <inertial>
      <origin xyz="0.0 0.0 0.0" rpy="0.0 -0.0 0.0"/>
      <mass value="1.0"/>
      <inertia ixx="1.0" ixy="0.0" ixz="0.0" iyy="1.0" iyz="0.0" izz="1.0"/>
    </inertial>
    <visual>
      <geometry>
        <sphere radius="0.015"/>
      </geometry>
      <origin xyz="0.0 0.0 0.0" rpy="0.0 -0.0 0.0"/>
    </visual>
  </link>
  <link name="f31_base">
    <inertial>
      <origin xyz="0.0 0.0 0.0" rpy="0.0 -0.0 0.0"/>
      <mass value="1.0"/>
      <inertia ixx="1.0" ixy="0.0" ixz="0.0" iyy="1.0" iyz="0.0" izz="1.0"/>
    </inertial>
    <visual>
      <geometry>
        <sphere radius="0.015"/>
      </geometry>
      <origin xyz="0.0 0.0 0.0" rpy="0.0 -0.0 0.0"/>
    </visual>
  </link>
  <link name="f32_slot">
    <inertial>
      <origin xyz="0.0 0.0 0.0" rpy="0.0 -0.0 0.0"/>
      <mass value="1.0"/>
      <inertia ixx="1.0" ixy="0.0" ixz="0.0" iyy="1.0" iyz="0.0" izz="1.0"/>
    </inertial>
    <visual>
      <geometry>
        <sphere radius="0.015"/>
      </geometry>
      <origin xyz="0.0 0.0 0.0" rpy="0.0 -0.0 0.0"/>
    </visual>
  </link>
  <joint name="f11_joint" type="revolute">
    <dynamics damping="100.0" friction="1.0"/>
    <limit effort="30.0" velocity="2.0" lower="-0.4" upper="0.25"/>
    <parent link="f11_base"/>
    <child link="f11"/>
    <axis xyz="0. 1. 0."/>
    <origin xyz="0.0 0.0 0.0" rpy="0.0 0.25 0.0"/>
  </joint>
  <joint name="f12_joint" type="revolute">
    <dynamics damping="100.0" friction="1.0"/>
    <limit effort="30.0" velocity="2.0" lower="-0.65" upper="0.0"/>
    <mimic joint="f11_joint" multiplier="2.0" offset="-0.25"/>
    <parent link="f12_slot"/>
    <child link="f12"/>
    <axis xyz="0. 1. 0."/>
    <origin xyz="0.0 0.0 0.0" rpy="0.0 -0.0 0.0"/>
  </joint>
  <joint name="f21_joint" type="revolute">
    <dynamics damping="100.0" friction="1.0"/>
    <limit effort="30.0" velocity="2.0" lower="-0.4" upper="0.25"/>
    <parent link="f21_base"/>
    <child link="f21"/>
    <axis xyz=" 0.70710678 -0.70710678  0.        "/>
    <origin xyz="0.0 0.0 0.0" rpy="0.25 -0.25 0.0"/>
  </joint>
  <joint name="f22_joint" type="revolute">
    <dynamics damping="100.0" friction="1.0"/>
    <limit effort="30.0" velocity="2.0" lower="-0.65" upper="0.0"/>
    <mimic joint="f21_joint" multiplier="1.0" offset="-0.25"/>
    <parent link="f22_slot"/>
    <child link="f22"/>
    <axis xyz=" 0.70710678 -0.70710678  0.        "/>
    <origin xyz="0.0 0.0 0.0" rpy="0.0 -0.0 0.0"/>
  </joint>
  <joint name="f31_joint" type="revolute">
    <dynamics damping="100.0" friction="1.0"/>
    <limit effort="30.0" velocity="2.0" lower="-0.4" upper="0.25"/>
    <parent link="f31_base"/>
    <child link="f31"/>
    <axis xyz="-0.70710678 -0.70710678  0.        "/>
    <origin xyz="0.0 0.0 0.0" rpy="-0.25 -0.25 0.0"/>
  </joint>
  <joint name="f32_joint" type="revolute">
    <dynamics damping="100.0" friction="1.0"/>
    <limit effort="30.0" velocity="2.0" lower="-0.65" upper="0.0"/>
    <mimic joint="f31_joint" multiplier="1.0" offset="-0.25"/>
    <parent link="f32_slot"/>
    <child link="f32"/>
    <axis xyz="-0.70710678 -0.70710678  0.        "/>
    <origin xyz="0.0 0.0 0.0" rpy="0.0 -0.0 0.0"/>
  </joint>
  <joint name="f11_base_joint" type="fixed">
    <parent link="palm"/>
    <child link="f11_base"/>
    <axis xyz="1. 0. 0."/>
    <origin xyz="0.05 0.0 0.0" rpy="0.0 0.0 0.0"/>
  </joint>
  <joint name="f12_slot_joint" type="fixed">
    <parent link="f11"/>
    <child link="f12_slot"/>
    <axis xyz="1. 0. 0."/>
    <origin xyz="0.0 0.0 0.047548421118199145" rpy="0.0 0.0 0.0"/>
  </joint>
  <joint name="f21_base_joint" type="fixed">
    <parent link="palm"/>
    <child link="f21_base"/>
    <axis xyz="1. 0. 0."/>
    <origin xyz="-0.025 -0.043301270189222 0.0" rpy="0.0 0.0 0.0"/>
  </joint>
  <joint name="f22_slot_joint" type="fixed">
    <parent link="f21"/>
    <child link="f22_slot"/>
    <axis xyz="1. 0. 0."/>
    <origin xyz="0.0 0.0 0.047548421118199145" rpy="0.0 0.0 0.0"/>
  </joint>
  <joint name="f31_base_joint" type="fixed">
    <parent link="palm"/>
    <child link="f31_base"/>
    <axis xyz="1. 0. 0."/>
    <origin xyz="-0.025 0.043301270189222 0.0" rpy="0.0 0.0 0.0"/>
  </joint>
  <joint name="f32_slot_joint" type="fixed">
    <parent link="f31"/>
    <child link="f32_slot"/>
    <axis xyz="1. 0. 0."/>
    <origin xyz="0.0 0.0 0.047548421118199145" rpy="0.0 0.0 0.0"/>
  </joint>
  <material name="blue">
    <color rgba="0.  0.  0.8 1. "/>
  </material>
  <material name="green">
    <color rgba="0. 1. 0. 1."/>
  </material>
</robot>
