<?xml version="1.0"?>
<robot name="gripper_2f_1j">
    <link name="palm">
        <inertia>
            <mass value='3.0'/>
            <origin xyz='0 0 0'/>
            <inertia ixx="1.0" ixy="0.0" ixz="0.0" iyy="1.0" iyz="0.0" izz="1.0"/>
        </inertia>
        <visual>
            <geometry>
                <cylinder length="0.03" radius="0.05"/>
            </geometry>
            <material name="blue">
                <color rgba="0 0 .8 1"/>
            </material>
        </visual>
        <collision>
            <origin rpy="0 0 0 " xyz="0 0 0"/>
            <geometry>
                <cylinder length="0.03" radius="0.05"/>
            </geometry>
            <contact_coefficients kd="1.0" kp="10000.0" mu="1.5"/>
        </collision>
    </link>

    <link name='f11'>
        <inertia>
            <mass value='.1'/>
            <inertia ixx="0.01" ixy="0" ixz="0" iyy="0.01" iyz="0" izz="0.01"/>
        </inertia>
        <visual>
            <origin xyz='0 0 .05'/>
            <geometry>
                <cylinder length='.1' radius='.01'/>
            </geometry>
            <material name='green'>
                <color rgba='0 1 0 1'/>
            </material>
        </visual>
        <collision>
            <origin rpy="0 0 0 " xyz="0 0 0.05"/>
            <geometry>
                <cylinder length='.1' radius='.01'/>
            </geometry>
            <contact_coefficients kd="1.0" kp="10000.0" mu="1"/>
        </collision>
    </link>
    <link name='f21'>
        <inertia>
            <mass value='.1'/>
            <inertia ixx="0.01" ixy="0" ixz="0" iyy="0.01" iyz="0" izz="0.01"/>
        </inertia>
        <visual>
            <origin xyz='0 0 .05'/>
            <geometry>
                <cylinder length='.1' radius='.01'/>
            </geometry>
            <material name='green'>
                <color rgba='0 1 0 1'/>
            </material>
        </visual>
        <collision>
            <origin rpy="0 0 0 " xyz="0 0 0.05"/>
            <geometry>
                <cylinder length='.1' radius='.01'/>
            </geometry>
            <contact_coefficients kd="1.0" kp="10000.0" mu="1"/>
        </collision>
    </link>


    <link name='f11_base'>
        <visual>
            <origin xyz='0 0 0'/>
            <geometry>
                <sphere radius='.015'/>
            </geometry>
        </visual>
    </link>
    <link name='f21_base'>
        <visual>
            <origin xyz='0 0 0'/>
            <geometry>
                <sphere radius='.015'/>
            </geometry>
        </visual>
    </link>


    <joint name='f11_joint' type="revolute">
        <origin xyz="0 0 .0" rpy="0 .25 0"/>
        <parent link='f11_base'/>
        <child link='f11'/>
        <axis xyz='0 1 0'/>
        <dynamics damping='100.0' friction='1.0'/>
        <limit effort='30' lower='-.6' upper='.25' velocity='2.0'/>
    </joint>
    <joint name='f21_joint' type="revolute">
        <origin xyz="0 0 .0" rpy=".0 -.25 0"/>
        <parent link='f21_base'/>
        <child link='f21'/>
        <axis xyz='0 -1 0'/>
        <dynamics damping='100.0' friction='1.0'/>
        <limit effort='30' lower='-.6' upper='.25' velocity='2.0'/>
    </joint>



    <joint name='f11_base_joint' type="fixed">
        <origin xyz=".05 0 .0" rpy="0 0 0"/>
        <parent link='palm'/>
        <child link='f11_base'/>
    </joint>

    <joint name='f21_base_joint' type="fixed">
        <origin xyz="-.05 -0.0 .0" rpy="0 0 0"/>
        <parent link='palm'/>
        <child link='f21_base'/>
    </joint>

    
</robot>