<?xml version="1.0"?>
<robot name="gripper_3f_2j">
  <link name="base">
    <inertial>
      <origin xyz="0.0 0.0 0.0" rpy="0.0 0.0 0.0"/>
      <mass value="0.01"/>
      <inertia ixx="0.0" ixy="0.0" ixz="0.0" iyy="0.0" iyz="0.0" izz="0.0"/>
    </inertial>
    <visual>
      <geometry>
        <sphere radius="0.0015"/>
      </geometry>
      <origin xyz="0.0 0.0 0.0" rpy="0.0 -0.0 0.0"/>
    </visual>
  </link>

  <link name="palm">
    <inertial>
      <origin xyz="0.0 0.0 0.0" rpy="0.0 -0.0 0.0"/>
      <mass value="1.0"/>
      <inertia ixx="1.0" ixy="0.0" ixz="0.0" iyy="1.0" iyz="0.0" izz="1.0"/>
    </inertial>
    <visual>
      <geometry>
        <cylinder radius="0.05" length="0.03"/>
      </geometry>
      <material name="blue"/>
      <origin xyz="0.0 0.0 0.0" rpy="0.0 -0.0 0.0"/>
    </visual>
    <collision>
      <geometry>
        <cylinder radius="0.05" length="0.03"/>
      </geometry>
      <origin xyz="0.0 0.0 0.0" rpy="0.0 0.0 0.0"/>
    </collision>
  </link>

    <joint name="base" type="prismatic">
        <parent link="base"/>
        <child link="palm"/>
        <limit effort="1000.0" lower="-0.3" upper=".1" velocity="0.5"/>
        <origin rpy="0 0 0" xyz="0. 0 0."/>
        <axis xyz='0 0 1'/>
    </joint>

  <link name="f11">
    <inertial>
      <origin xyz="0.0 0.0 0.0" rpy="0.0 -0.0 0.0"/>
      <mass value="1.0"/>
      <inertia ixx="1.0" ixy="0.0" ixz="0.0" iyy="1.0" iyz="0.0" izz="1.0"/>
    </inertial>
    <visual>
      <geometry>
        <cylinder radius="0.01" length="0.05"/>
      </geometry>
      <material name="green"/>
      <origin xyz="0.0 0.0 0.025" rpy="0.0 -0.0 0.0"/>
    </visual>
    <collision>
      <geometry>
        <cylinder radius="0.01" length="0.05"/>
      </geometry>
      <origin xyz="0.0 0.0 0.025" rpy="0.0 0.0 0.0"/>
    </collision>
  </link>
  <link name="f12">
    <inertial>
      <origin xyz="0.0 0.0 0.0" rpy="0.0 -0.0 0.0"/>
      <mass value="1.0"/>
      <inertia ixx="1.0" ixy="0.0" ixz="0.0" iyy="1.0" iyz="0.0" izz="1.0"/>
    </inertial>
    <visual>
      <geometry>
        <cylinder radius="0.01" length="0.05"/>
      </geometry>
      <material name="green"/>
      <origin xyz="0.0 0.0 0.025" rpy="0.0 -0.0 0.0"/>
    </visual>
    <collision>
      <geometry>
        <cylinder radius="0.01" length="0.05"/>
      </geometry>
      <origin xyz="0.0 0.0 0.025" rpy="0.0 0.0 0.0"/>
    </collision>
  </link>
  <link name="f21">
    <inertial>
      <origin xyz="0.0 0.0 0.0" rpy="0.0 -0.0 0.0"/>
      <mass value="1.0"/>
      <inertia ixx="1.0" ixy="0.0" ixz="0.0" iyy="1.0" iyz="0.0" izz="1.0"/>
    </inertial>
    <visual>
      <geometry>
        <cylinder radius="0.01" length="0.05"/>
      </geometry>
      <material name="green"/>
      <origin xyz="0.0 0.0 0.025" rpy="0.0 -0.0 0.0"/>
    </visual>
    <collision>
      <geometry>
        <cylinder radius="0.01" length="0.05"/>
      </geometry>
      <origin xyz="0.0 0.0 0.025" rpy="0.0 0.0 0.0"/>
    </collision>
  </link>
  <link name="f22">
    <inertial>
      <origin xyz="0.0 0.0 0.0" rpy="0.0 -0.0 0.0"/>
      <mass value="1.0"/>
      <inertia ixx="1.0" ixy="0.0" ixz="0.0" iyy="1.0" iyz="0.0" izz="1.0"/>
    </inertial>
    <visual>
      <geometry>
        <cylinder radius="0.01" length="0.05"/>
      </geometry>
      <material name="green"/>
      <origin xyz="0.0 0.0 0.025" rpy="0.0 -0.0 0.0"/>
    </visual>
    <collision>
      <geometry>
        <cylinder radius="0.01" length="0.05"/>
      </geometry>
      <origin xyz="0.0 0.0 0.025" rpy="0.0 0.0 0.0"/>
    </collision>
  </link>
  <link name="f31">
    <inertial>
      <origin xyz="0.0 0.0 0.0" rpy="0.0 -0.0 0.0"/>
      <mass value="1.0"/>
      <inertia ixx="1.0" ixy="0.0" ixz="0.0" iyy="1.0" iyz="0.0" izz="1.0"/>
    </inertial>
    <visual>
      <geometry>
        <cylinder radius="0.01" length="0.05"/>
      </geometry>
      <material name="green"/>
      <origin xyz="0.0 0.0 0.025" rpy="0.0 -0.0 0.0"/>
    </visual>
    <collision>
      <geometry>
        <cylinder radius="0.01" length="0.05"/>
      </geometry>
      <origin xyz="0.0 0.0 0.025" rpy="0.0 0.0 0.0"/>
    </collision>
  </link>
  <link name="f32">
    <inertial>
      <origin xyz="0.0 0.0 0.0" rpy="0.0 -0.0 0.0"/>
      <mass value="1.0"/>
      <inertia ixx="1.0" ixy="0.0" ixz="0.0" iyy="1.0" iyz="0.0" izz="1.0"/>
    </inertial>
    <visual>
      <geometry>
        <cylinder radius="0.01" length="0.05"/>
      </geometry>
      <material name="green"/>
      <origin xyz="0.0 0.0 0.025" rpy="0.0 -0.0 0.0"/>
    </visual>
    <collision>
      <geometry>
        <cylinder radius="0.01" length="0.05"/>
      </geometry>
      <origin xyz="0.0 0.0 0.025" rpy="0.0 0.0 0.0"/>
    </collision>
  </link>
  <link name="f11_base">
    <inertial>
      <origin xyz="0.0 0.0 0.0" rpy="0.0 0.0 0.0"/>
      <mass value="0.01"/>
      <inertia ixx="0.0" ixy="0.0" ixz="0.0" iyy="0.0" iyz="0.0" izz="0.0"/>
    </inertial>
    <visual>
      <geometry>
        <sphere radius="0.015"/>
      </geometry>
      <origin xyz="0.0 0.0 0.0" rpy="0.0 -0.0 0.0"/>
    </visual>
  </link>
  <link name="f12_slot">
    <inertial>
      <origin xyz="0.0 0.0 0.0" rpy="0.0 0.0 0.0"/>
      <mass value="0.01"/>
      <inertia ixx="0.0" ixy="0.0" ixz="0.0" iyy="0.0" iyz="0.0" izz="0.0"/>
    </inertial>
    <visual>
      <geometry>
        <sphere radius="0.015"/>
      </geometry>
      <origin xyz="0.0 0.0 0.0" rpy="0.0 -0.0 0.0"/>
    </visual>
  </link>
  <link name="f21_base">
    <inertial>
      <origin xyz="0.0 0.0 0.0" rpy="0.0 0.0 0.0"/>
      <mass value="0.01"/>
      <inertia ixx="0.0" ixy="0.0" ixz="0.0" iyy="0.0" iyz="0.0" izz="0.0"/>
    </inertial>
    <visual>
      <geometry>
        <sphere radius="0.015"/>
      </geometry>
      <origin xyz="0.0 0.0 0.0" rpy="0.0 -0.0 0.0"/>
    </visual>
  </link>
  <link name="f22_slot">
    <inertial>
      <origin xyz="0.0 0.0 0.0" rpy="0.0 0.0 0.0"/>
      <mass value="0.01"/>
      <inertia ixx="0.0" ixy="0.0" ixz="0.0" iyy="0.0" iyz="0.0" izz="0.0"/>
    </inertial>
    <visual>
      <geometry>
        <sphere radius="0.015"/>
      </geometry>
      <origin xyz="0.0 0.0 0.0" rpy="0.0 -0.0 0.0"/>
    </visual>
  </link>
  <link name="f31_base">
    <inertial>
      <origin xyz="0.0 0.0 0.0" rpy="0.0 0.0 0.0"/>
      <mass value="0.0"/>
      <inertia ixx="0.0" ixy="0.0" ixz="0.0" iyy="0.0" iyz="0.0" izz="0.0"/>
    </inertial>
    <visual>
      <geometry>
        <sphere radius="0.015"/>
      </geometry>
      <origin xyz="0.0 0.0 0.0" rpy="0.0 -0.0 0.0"/>
    </visual>
  </link>
  <link name="f32_slot">
    <inertial>
      <origin xyz="0.0 0.0 0.0" rpy="0.0 0.0 0.0"/>
      <mass value="0.0"/>
      <inertia ixx="0.0" ixy="0.0" ixz="0.0" iyy="0.0" iyz="0.0" izz="0.0"/>
    </inertial>
    <visual>
      <geometry>
        <sphere radius="0.015"/>
      </geometry>
      <origin xyz="0.0 0.0 0.0" rpy="0.0 -0.0 0.0"/>
    </visual>
  </link>
  <link name="f13_slot">
    <inertial>
      <origin xyz="0.0 0.0 0.0" rpy="0.0 0.0 0.0"/>
      <mass value="0.0"/>
      <inertia ixx="0.0" ixy="0.0" ixz="0.0" iyy="0.0" iyz="0.0" izz="0.0"/>
    </inertial>
    <visual>
      <geometry>
        <sphere radius="0.015"/>
      </geometry>
      <origin xyz="0.0 0.0 0.0" rpy="0.0 -0.0 0.0"/>
    </visual>
  </link>
  <link name="f23_slot">
    <inertial>
      <origin xyz="0.0 0.0 0.0" rpy="0.0 0.0 0.0"/>
      <mass value="0.0"/>
      <inertia ixx="0.0" ixy="0.0" ixz="0.0" iyy="0.0" iyz="0.0" izz="0.0"/>
    </inertial>
    <visual>
      <geometry>
        <sphere radius="0.015"/>
      </geometry>
      <origin xyz="0.0 0.0 0.0" rpy="0.0 -0.0 0.0"/>
    </visual>
  </link>
  <link name="f33_slot">
    <inertial>
      <origin xyz="0.0 0.0 0.0" rpy="0.0 0.0 0.0"/>
      <mass value="0.0"/>
      <inertia ixx="0.0" ixy="0.0" ixz="0.0" iyy="0.0" iyz="0.0" izz="0.0"/>
    </inertial>
    <visual>
      <geometry>
        <sphere radius="0.015"/>
      </geometry>
      <origin xyz="0.0 0.0 0.0" rpy="0.0 -0.0 0.0"/>
    </visual>
  </link>

  <joint name="f11_joint" type="revolute">
    <dynamics damping="100.0" friction="1.0"/>
    <limit effort="30.0" velocity="2.0" lower="-0.4" upper="0.25"/>
    <parent link="f11_base"/>
    <child link="f11"/>
    <axis xyz="0 1 0"/>
    <origin xyz="0.0 0.0 0.0" rpy="0.0 0.25 0.0"/>
  </joint>
  <joint name="f12_joint" type="revolute">
    <dynamics damping="100.0" friction="1.0"/>
    <limit effort="30.0" velocity="2.0" lower="-0.65" upper="0.0"/>
    <mimic joint="f11_joint" multiplier="2.0" offset="-0.25"/>
    <parent link="f12_slot"/>
    <child link="f12"/>
    <axis xyz="0 1 0"/>
    <origin xyz="0.0 0.0 0.0" rpy="0.0 -0.0 0.0"/>
  </joint>
  <joint name="f21_joint" type="revolute">
    <dynamics damping="100.0" friction="1.0"/>
    <limit effort="30.0" velocity="2.0" lower="-0.4" upper="0.25"/>
    <parent link="f21_base"/>
    <child link="f21"/>
    <axis xyz="0.7071067811865475 -0.7071067811865475  0"/>
    <origin xyz="0.0 0.0 0.0" rpy="0.25 -0.25 0.0"/>
  </joint>
  <joint name="f22_joint" type="revolute">
    <dynamics damping="100.0" friction="1.0"/>
    <limit effort="30.0" velocity="2.0" lower="-0.65" upper="0.0"/>
    <mimic joint="f21_joint" multiplier="1.0" offset="-0.25"/>
    <parent link="f22_slot"/>
    <child link="f22"/>
    <axis xyz=" 0.7071067811865475 -0.7071067811865475  0"/>
    <origin xyz="0.0 0.0 0.0" rpy="0.0 -0.0 0.0"/>
  </joint>
  <joint name="f31_joint" type="revolute">
    <dynamics damping="100.0" friction="1.0"/>
    <limit effort="30.0" velocity="2.0" lower="-0.4" upper="0.25"/>
    <parent link="f31_base"/>
    <child link="f31"/>
    <axis xyz="-0.7071067811865475 -0.7071067811865475  0"/>
    <origin xyz="0.0 0.0 0.0" rpy="-0.25 -0.25 0.0"/>
  </joint>
  <joint name="f32_joint" type="revolute">
    <dynamics damping="100.0" friction="1.0"/>
    <limit effort="30.0" velocity="2.0" lower="-0.65" upper="0."/>
    <mimic joint="f31_joint" multiplier="1.0" offset="-0.25"/>
    <parent link="f32_slot"/>
    <child link="f32"/>
    <axis xyz="-0.7071067811865475 -0.7071067811865475  0"/>
    <origin xyz="0.0 0.0 0.0" rpy="0.0 0.0 0.0"/>
  </joint>
  <joint name="f11_base_joint" type="fixed">
    <parent link="palm"/>
    <child link="f11_base"/>
    <axis xyz="1 0 0"/>
    <origin xyz="0.05 0.0 0.0" rpy="0.0 0.0 0.0"/>
  </joint>
  <joint name="f12_slot_joint" type="fixed">
    <parent link="f11"/>
    <child link="f12_slot"/>
    <axis xyz="1 0 0"/>
    <origin xyz="0.0 0.0 0.05" rpy="0.0 0.0 0.0"/>
  </joint>
  <joint name="f21_base_joint" type="fixed">
    <parent link="palm"/>
    <child link="f21_base"/>
    <axis xyz="1 0 0"/>
    <origin xyz="-0.025 -0.043301270189222 0.0" rpy="0.0 0.0 0.0"/>
  </joint>
  <joint name="f22_slot_joint" type="fixed">
    <parent link="f21"/>
    <child link="f22_slot"/>
    <axis xyz="1 0 0"/>
    <origin xyz="0.0 0.0 0.05" rpy="0.0 0.0 0.0"/>
  </joint>
  <joint name="f31_base_joint" type="fixed">
    <parent link="palm"/>
    <child link="f31_base"/>
    <axis xyz="1 0 0"/>
    <origin xyz="-0.025 0.043301270189222 0.0" rpy="0.0 0.0 0.0"/>
  </joint>
  <joint name="f32_slot_joint" type="fixed">
    <parent link="f31"/>
    <child link="f32_slot"/>
    <axis xyz="1 0 0"/>
    <origin xyz="0.0 0.0 0.05" rpy="0.0 0.0 0.0"/>
  </joint>
  <joint name="f13_slot_joint" type="fixed">
    <parent link="f12"/>
    <child link="f13_slot"/>
    <axis xyz="1 0. 0."/>
    <origin xyz="0.0 0.0 0.05" rpy="0.0 0.0 0.0"/>
  </joint>
  <joint name="f23_slot_joint" type="fixed">
    <parent link="f22"/>
    <child link="f23_slot"/>
    <axis xyz="1. 0. 0."/>
    <origin xyz="0.0 0.0 0.05" rpy="0.0 0.0 0.0"/>
  </joint>
  <joint name="f33_slot_joint" type="fixed">
    <parent link="f32"/>
    <child link="f33_slot"/>
    <axis xyz="1. 0. 0."/>
    <origin xyz="0.0 0.0 0.05" rpy="0.0 0.0 0.0"/>
  </joint>
  <material name="LightGrey">
    <color rgba="0.7 0.7 0.7 1. "/>
  </material>

</robot>