<?xml version='1.0' encoding='UTF-8'?>
<robot name="ur5_3f2j">
  <link name="base_link">
    <inertial>
      <origin xyz="0.0 0.0 0.0" rpy="0.0 0.0 0.0"/>
      <mass value="4.0"/>
      <inertia ixx="0.00443333156" ixy="0.0" ixz="0.0" iyy="0.00443333156" iyz="0.0" izz="0.0072"/>
    </inertial>
    <visual>
      <geometry>
        <mesh filename="meshes/ur5/visual/base.obj"/>
      </geometry>
      <material name="LightGrey"/>
      <origin xyz="0.0 0.0 0.0" rpy="0.0 -0.0 0.0"/>
    </visual>
    <collision>
      <geometry>
        <mesh filename="meshes/ur5/collision/base.stl"/>
      </geometry>
      <origin xyz="0.0 0.0 0.0" rpy="0.0 -0.0 0.0"/>
    </collision>
  </link>
  <link name="shoulder_link">
    <inertial>
      <origin xyz="0.0 0.0 0.0" rpy="0.0 0.0 0.0"/>
      <mass value="3.7"/>
      <inertia ixx="0.010267495893" ixy="0.0" ixz="0.0" iyy="0.010267495893" iyz="0.0" izz="0.00666"/>
    </inertial>
    <visual>
      <geometry>
        <mesh filename="meshes/ur5/visual/shoulder.obj"/>
      </geometry>
      <material name="LightGrey"/>
      <origin xyz="0.0 0.0 0.0" rpy="0.0 -0.0 0.0"/>
    </visual>
    <collision>
      <geometry>
        <mesh filename="meshes/ur5/collision/shoulder.stl"/>
      </geometry>
      <origin xyz="0.0 0.0 0.0" rpy="0.0 -0.0 0.0"/>
    </collision>
  </link>
  <link name="upper_arm_link">
    <inertial>
      <origin xyz="0.0 0.0 0.28" rpy="0.0 0.0 0.0"/>
      <mass value="8.393"/>
      <inertia ixx="0.22689067591" ixy="0.0" ixz="0.0" iyy="0.22689067591" iyz="0.0" izz="0.0151074"/>
    </inertial>
    <visual>
      <geometry>
        <mesh filename="meshes/ur5/visual/upperarm.obj"/>
      </geometry>
      <material name="LightGrey"/>
      <origin xyz="0.0 0.0 0.0" rpy="0.0 -0.0 0.0"/>
    </visual>
    <collision>
      <geometry>
        <mesh filename="meshes/ur5/collision/upperarm.stl"/>
      </geometry>
      <origin xyz="0.0 0.0 0.0" rpy="0.0 -0.0 0.0"/>
    </collision>
  </link>
  <link name="forearm_link">
    <inertial>
      <origin xyz="0.0 0.0 0.25" rpy="0.0 0.0 0.0"/>
      <mass value="2.275"/>
      <inertia ixx="0.049443313556" ixy="0.0" ixz="0.0" iyy="0.049443313556" iyz="0.0" izz="0.004095"/>
    </inertial>
    <visual>
      <geometry>
        <mesh filename="meshes/ur5/visual/forearm.obj"/>
      </geometry>
      <material name="LightGrey"/>
      <origin xyz="0.0 0.0 0.0" rpy="0.0 -0.0 0.0"/>
    </visual>
    <collision>
      <geometry>
        <mesh filename="meshes/ur5/collision/forearm.stl"/>
      </geometry>
      <origin xyz="0.0 0.0 0.0" rpy="0.0 -0.0 0.0"/>
    </collision>
  </link>
  <link name="wrist_1_link">
    <inertial>
      <origin xyz="0.0 0.0 0.0" rpy="0.0 0.0 0.0"/>
      <mass value="1.219"/>
      <inertia ixx="0.111172755531" ixy="0.0" ixz="0.0" iyy="0.111172755531" iyz="0.0" izz="0.21942"/>
    </inertial>
    <visual>
      <geometry>
        <mesh filename="meshes/ur5/visual/wrist1.obj"/>
      </geometry>
      <material name="LightGrey"/>
      <origin xyz="0.0 0.0 0.0" rpy="0.0 -0.0 0.0"/>
    </visual>
    <collision>
      <geometry>
        <mesh filename="meshes/ur5/collision/wrist1.stl"/>
      </geometry>
      <origin xyz="0.0 0.0 0.0" rpy="0.0 -0.0 0.0"/>
    </collision>
  </link>
  <link name="wrist_2_link">
    <inertial>
      <origin xyz="0.0 0.0 0.0" rpy="0.0 0.0 0.0"/>
      <mass value="1.219"/>
      <inertia ixx="0.111172755531" ixy="0.0" ixz="0.0" iyy="0.111172755531" iyz="0.0" izz="0.21942"/>
    </inertial>
    <visual>
      <geometry>
        <mesh filename="meshes/ur5/visual/wrist2.obj"/>
      </geometry>
      <material name="LightGrey"/>
      <origin xyz="0.0 0.0 0.0" rpy="0.0 -0.0 0.0"/>
    </visual>
    <collision>
      <geometry>
        <mesh filename="meshes/ur5/collision/wrist2.stl"/>
      </geometry>
      <origin xyz="0.0 0.0 0.0" rpy="0.0 -0.0 0.0"/>
    </collision>
  </link>
  <link name="wrist_3_link">
    <inertial>
      <origin xyz="0.0 0.0 0.0" rpy="0.0 0.0 0.0"/>
      <mass value="0.1879"/>
      <inertia ixx="0.0171364731454" ixy="0.0" ixz="0.0" iyy="0.0171364731454" iyz="0.0" izz="0.033822"/>
    </inertial>
    <visual>
      <geometry>
        <mesh filename="meshes/ur5/visual/wrist3.obj"/>
      </geometry>
      <material name="LightGrey"/>
      <origin xyz="0.0 0.0 0.0" rpy="0.0 -0.0 0.0"/>
    </visual>
    <collision>
      <geometry>
        <mesh filename="meshes/ur5/collision/wrist3.stl"/>
      </geometry>
      <origin xyz="0.0 0.0 0.0" rpy="0.0 -0.0 0.0"/>
    </collision>
  </link>
  <link name="ee_link">
    <inertial>
      <origin xyz="0.0 0.0 0.0" rpy="0.0 0.0 0.0"/>
      <mass value="0.0"/>
      <inertia ixx="0.0" ixy="0.0" ixz="0.0" iyy="0.0" iyz="0.0" izz="0.0"/>
    </inertial>
    <collision>
      <geometry>
        <box size="0.01 0.01 0.01"/>
      </geometry>
      <origin xyz="-0.01 0.0 0.0" rpy="0.0 0.0 0.0"/>
    </collision>
  </link>
  <link name="palm">
    <inertial>
      <origin xyz="0.0 0.0 0.0" rpy="0.0 -0.0 0.0"/>
      <mass value="1.0"/>
      <inertia ixx="1.0" ixy="0.0" ixz="0.0" iyy="1.0" iyz="0.0" izz="1.0"/>
    </inertial>
    <visual>
      <geometry>
        <cylinder radius="0.05" length="0.03"/>
      </geometry>
      <material name="blue"/>
      <origin xyz="0.0 0.0 0.0" rpy="0.0 -0.0 0.0"/>
    </visual>
    <collision>
      <geometry>
        <cylinder radius="0.05" length="0.03"/>
      </geometry>
      <origin xyz="0.0 0.0 0.0" rpy="0.0 0.0 0.0"/>
    </collision>
  </link>
  <link name="f11">
    <inertial>
      <origin xyz="0.0 0.0 0.0" rpy="0.0 -0.0 0.0"/>
      <mass value="1.0"/>
      <inertia ixx="1.0" ixy="0.0" ixz="0.0" iyy="1.0" iyz="0.0" izz="1.0"/>
    </inertial>
    <visual>
      <geometry>
        <cylinder radius="0.01068100461919942" length="0.08651739020966667"/>
      </geometry>
      <material name="green"/>
      <origin xyz="0.0 0.0 0.043258695104833336" rpy="0.0 -0.0 0.0"/>
    </visual>
    <collision>
      <geometry>
        <cylinder radius="0.01068100461919942" length="0.08651739020966667"/>
      </geometry>
      <origin xyz="0.0 0.0 0.025" rpy="0.0 0.0 0.0"/>
    </collision>
  </link>
  <link name="f12">
    <inertial>
      <origin xyz="0.0 0.0 0.0" rpy="0.0 -0.0 0.0"/>
      <mass value="1.0"/>
      <inertia ixx="1.0" ixy="0.0" ixz="0.0" iyy="1.0" iyz="0.0" izz="1.0"/>
    </inertial>
    <visual>
      <geometry>
        <cylinder radius="0.01068100461919942" length="0.07351870041463854"/>
      </geometry>
      <material name="green"/>
      <origin xyz="0.0 0.0 0.03675935020731927" rpy="0.0 -0.0 0.0"/>
    </visual>
    <collision>
      <geometry>
        <cylinder radius="0.01068100461919942" length="0.07351870041463854"/>
      </geometry>
      <origin xyz="0.0 0.0 0.025" rpy="0.0 0.0 0.0"/>
    </collision>
  </link>
  <link name="f21">
    <inertial>
      <origin xyz="0.0 0.0 0.0" rpy="0.0 -0.0 0.0"/>
      <mass value="1.0"/>
      <inertia ixx="1.0" ixy="0.0" ixz="0.0" iyy="1.0" iyz="0.0" izz="1.0"/>
    </inertial>
    <visual>
      <geometry>
        <cylinder radius="0.01068100461919942" length="0.08651739020966667"/>
      </geometry>
      <material name="green"/>
      <origin xyz="0.0 0.0 0.043258695104833336" rpy="0.0 -0.0 0.0"/>
    </visual>
    <collision>
      <geometry>
        <cylinder radius="0.01068100461919942" length="0.08651739020966667"/>
      </geometry>
      <origin xyz="0.0 0.0 0.025" rpy="0.0 0.0 0.0"/>
    </collision>
  </link>
  <link name="f22">
    <inertial>
      <origin xyz="0.0 0.0 0.0" rpy="0.0 -0.0 0.0"/>
      <mass value="1.0"/>
      <inertia ixx="1.0" ixy="0.0" ixz="0.0" iyy="1.0" iyz="0.0" izz="1.0"/>
    </inertial>
    <visual>
      <geometry>
        <cylinder radius="0.01068100461919942" length="0.07351870041463854"/>
      </geometry>
      <material name="green"/>
      <origin xyz="0.0 0.0 0.03675935020731927" rpy="0.0 -0.0 0.0"/>
    </visual>
    <collision>
      <geometry>
        <cylinder radius="0.01068100461919942" length="0.07351870041463854"/>
      </geometry>
      <origin xyz="0.0 0.0 0.025" rpy="0.0 0.0 0.0"/>
    </collision>
  </link>
  <link name="f31">
    <inertial>
      <origin xyz="0.0 0.0 0.0" rpy="0.0 -0.0 0.0"/>
      <mass value="1.0"/>
      <inertia ixx="1.0" ixy="0.0" ixz="0.0" iyy="1.0" iyz="0.0" izz="1.0"/>
    </inertial>
    <visual>
      <geometry>
        <cylinder radius="0.01068100461919942" length="0.08651739020966667"/>
      </geometry>
      <material name="green"/>
      <origin xyz="0.0 0.0 0.043258695104833336" rpy="0.0 -0.0 0.0"/>
    </visual>
    <collision>
      <geometry>
        <cylinder radius="0.01068100461919942" length="0.08651739020966667"/>
      </geometry>
      <origin xyz="0.0 0.0 0.025" rpy="0.0 0.0 0.0"/>
    </collision>
  </link>
  <link name="f32">
    <inertial>
      <origin xyz="0.0 0.0 0.0" rpy="0.0 -0.0 0.0"/>
      <mass value="1.0"/>
      <inertia ixx="1.0" ixy="0.0" ixz="0.0" iyy="1.0" iyz="0.0" izz="1.0"/>
    </inertial>
    <visual>
      <geometry>
        <cylinder radius="0.01068100461919942" length="0.07351870041463854"/>
      </geometry>
      <material name="green"/>
      <origin xyz="0.0 0.0 0.03675935020731927" rpy="0.0 -0.0 0.0"/>
    </visual>
    <collision>
      <geometry>
        <cylinder radius="0.01068100461919942" length="0.07351870041463854"/>
      </geometry>
      <origin xyz="0.0 0.0 0.025" rpy="0.0 0.0 0.0"/>
    </collision>
  </link>
  <link name="f11_base">
    <inertial>
      <origin xyz="0.0 0.0 0.0" rpy="0.0 0.0 0.0"/>
      <mass value="0.01"/>
      <inertia ixx="0.0" ixy="0.0" ixz="0.0" iyy="0.0" iyz="0.0" izz="0.0"/>
    </inertial>
    <visual>
      <geometry>
        <sphere radius="0.015"/>
      </geometry>
      <origin xyz="0.0 0.0 0.0" rpy="0.0 -0.0 0.0"/>
    </visual>
  </link>
  <link name="f12_slot">
    <inertial>
      <origin xyz="0.0 0.0 0.0" rpy="0.0 0.0 0.0"/>
      <mass value="0.01"/>
      <inertia ixx="0.0" ixy="0.0" ixz="0.0" iyy="0.0" iyz="0.0" izz="0.0"/>
    </inertial>
    <visual>
      <geometry>
        <sphere radius="0.015"/>
      </geometry>
      <origin xyz="0.0 0.0 0.0" rpy="0.0 -0.0 0.0"/>
    </visual>
  </link>
  <link name="f21_base">
    <inertial>
      <origin xyz="0.0 0.0 0.0" rpy="0.0 0.0 0.0"/>
      <mass value="0.01"/>
      <inertia ixx="0.0" ixy="0.0" ixz="0.0" iyy="0.0" iyz="0.0" izz="0.0"/>
    </inertial>
    <visual>
      <geometry>
        <sphere radius="0.015"/>
      </geometry>
      <origin xyz="0.0 0.0 0.0" rpy="0.0 -0.0 0.0"/>
    </visual>
  </link>
  <link name="f22_slot">
    <inertial>
      <origin xyz="0.0 0.0 0.0" rpy="0.0 0.0 0.0"/>
      <mass value="0.01"/>
      <inertia ixx="0.0" ixy="0.0" ixz="0.0" iyy="0.0" iyz="0.0" izz="0.0"/>
    </inertial>
    <visual>
      <geometry>
        <sphere radius="0.015"/>
      </geometry>
      <origin xyz="0.0 0.0 0.0" rpy="0.0 -0.0 0.0"/>
    </visual>
  </link>
  <link name="f31_base">
    <inertial>
      <origin xyz="0.0 0.0 0.0" rpy="0.0 0.0 0.0"/>
      <mass value="0.0"/>
      <inertia ixx="0.0" ixy="0.0" ixz="0.0" iyy="0.0" iyz="0.0" izz="0.0"/>
    </inertial>
    <visual>
      <geometry>
        <sphere radius="0.015"/>
      </geometry>
      <origin xyz="0.0 0.0 0.0" rpy="0.0 -0.0 0.0"/>
    </visual>
  </link>
  <link name="f32_slot">
    <inertial>
      <origin xyz="0.0 0.0 0.0" rpy="0.0 0.0 0.0"/>
      <mass value="0.0"/>
      <inertia ixx="0.0" ixy="0.0" ixz="0.0" iyy="0.0" iyz="0.0" izz="0.0"/>
    </inertial>
    <visual>
      <geometry>
        <sphere radius="0.015"/>
      </geometry>
      <origin xyz="0.0 0.0 0.0" rpy="0.0 -0.0 0.0"/>
    </visual>
  </link>
  <link name="f13_slot">
    <inertial>
      <origin xyz="0.0 0.0 0.0" rpy="0.0 0.0 0.0"/>
      <mass value="0.0"/>
      <inertia ixx="0.0" ixy="0.0" ixz="0.0" iyy="0.0" iyz="0.0" izz="0.0"/>
    </inertial>
    <visual>
      <geometry>
        <sphere radius="0.015"/>
      </geometry>
      <origin xyz="0.0 0.0 0.0" rpy="0.0 -0.0 0.0"/>
    </visual>
  </link>
  <link name="f23_slot">
    <inertial>
      <origin xyz="0.0 0.0 0.0" rpy="0.0 0.0 0.0"/>
      <mass value="0.0"/>
      <inertia ixx="0.0" ixy="0.0" ixz="0.0" iyy="0.0" iyz="0.0" izz="0.0"/>
    </inertial>
    <visual>
      <geometry>
        <sphere radius="0.015"/>
      </geometry>
      <origin xyz="0.0 0.0 0.0" rpy="0.0 -0.0 0.0"/>
    </visual>
  </link>
  <link name="f33_slot">
    <inertial>
      <origin xyz="0.0 0.0 0.0" rpy="0.0 0.0 0.0"/>
      <mass value="0.0"/>
      <inertia ixx="0.0" ixy="0.0" ixz="0.0" iyy="0.0" iyz="0.0" izz="0.0"/>
    </inertial>
    <visual>
      <geometry>
        <sphere radius="0.015"/>
      </geometry>
      <origin xyz="0.0 0.0 0.0" rpy="0.0 -0.0 0.0"/>
    </visual>
  </link>
  <joint name="shoulder_pan_joint" type="revolute">
    <dynamics damping="0.0" friction="0.0"/>
    <limit effort="150.0" velocity="3.15" lower="-3.14159265359" upper="3.14159265359"/>
    <parent link="base_link"/>
    <child link="shoulder_link"/>
    <axis xyz="0. 0. 1."/>
    <origin xyz="0.0 0.0 0.089159" rpy="0.0 0.0 0.0"/>
  </joint>
  <joint name="shoulder_lift_joint" type="revolute">
    <dynamics damping="0.0" friction="0.0"/>
    <limit effort="150.0" velocity="3.15" lower="-3.14159265359" upper="3.14159265359"/>
    <parent link="shoulder_link"/>
    <child link="upper_arm_link"/>
    <axis xyz="0. 1. 0."/>
    <origin xyz="0.0 0.13585 0.0" rpy="0.0 1.5707963267948966 0.0"/>
  </joint>
  <joint name="elbow_joint" type="revolute">
    <dynamics damping="0.0" friction="0.0"/>
    <limit effort="150.0" velocity="3.15" lower="-3.14159265359" upper="3.14159265359"/>
    <parent link="upper_arm_link"/>
    <child link="forearm_link"/>
    <axis xyz="0. 1. 0."/>
    <origin xyz="0.0 -0.1197 0.425" rpy="0.0 0.0 0.0"/>
  </joint>
  <joint name="wrist_1_joint" type="revolute">
    <dynamics damping="0.0" friction="0.0"/>
    <limit effort="28.0" velocity="3.2" lower="-6.28318530718" upper="6.28318530718"/>
    <parent link="forearm_link"/>
    <child link="wrist_1_link"/>
    <axis xyz="0. 1. 0."/>
    <origin xyz="0.0 0.0 0.39225" rpy="0.0 1.5707963267948966 0.0"/>
  </joint>
  <joint name="wrist_2_joint" type="revolute">
    <dynamics damping="0.0" friction="0.0"/>
    <limit effort="28.0" velocity="3.2" lower="-6.28318530718" upper="6.28318530718"/>
    <parent link="wrist_1_link"/>
    <child link="wrist_2_link"/>
    <axis xyz="0. 0. 1."/>
    <origin xyz="0.0 0.093 0.0" rpy="0.0 0.0 0.0"/>
  </joint>
  <joint name="wrist_3_joint" type="revolute">
    <dynamics damping="0.0" friction="0.0"/>
    <limit effort="28.0" velocity="3.2" lower="-6.28318530718" upper="6.28318530718"/>
    <parent link="wrist_2_link"/>
    <child link="wrist_3_link"/>
    <axis xyz="0. 1. 0."/>
    <origin xyz="0.0 0.0 0.09465" rpy="0.0 0.0 0.0"/>
  </joint>
  <joint name="ee_fixed_joint" type="fixed">
    <parent link="wrist_3_link"/>
    <child link="ee_link"/>
    <axis xyz="1. 0. 0."/>
    <origin xyz="0.0 0.0823 0.0" rpy="0.0 0.0 1.57079632679"/>
  </joint>
  <joint name="palm_ee_joint" type="fixed">
    <parent link="ee_link"/>
    <child link="palm"/>
    <axis xyz="1. 0. 0."/>
    <origin xyz="0.0 0.0 0.0" rpy="3.14 1.5699999999999876 3.14"/>
  </joint>
  <joint name="f11_joint" type="revolute">
    <dynamics damping="100.0" friction="1.0"/>
    <limit effort="30.0" velocity="2.0" lower="-0.4" upper="0.25"/>
    <parent link="f11_base"/>
    <child link="f11"/>
    <axis xyz="0. 1. 0."/>
    <origin xyz="0.0 0.0 0.0" rpy="0.0 0.25 0.0"/>
  </joint>
  <joint name="f12_joint" type="revolute">
    <dynamics damping="100.0" friction="1.0"/>
    <limit effort="30.0" velocity="2.0" lower="-0.4" upper="0.0"/>
    <mimic joint="f11_joint" multiplier="2.0" offset="-0.25"/>
    <parent link="f12_slot"/>
    <child link="f12"/>
    <axis xyz="0. 1. 0."/>
    <origin xyz="0.0 0.0 0.0" rpy="0.0 -0.0 0.0"/>
  </joint>
  <joint name="f21_joint" type="revolute">
    <dynamics damping="100.0" friction="1.0"/>
    <limit effort="30.0" velocity="2.0" lower="-0.4" upper="0.25"/>
    <parent link="f21_base"/>
    <child link="f21"/>
    <axis xyz=" 0.70710678 -0.70710678  0.        "/>
    <origin xyz="0.0 0.0 0.0" rpy="0.25 -0.25 0.0"/>
  </joint>
  <joint name="f22_joint" type="revolute">
    <dynamics damping="100.0" friction="1.0"/>
    <limit effort="30.0" velocity="2.0" lower="-0.4" upper="0.0"/>
    <mimic joint="f21_joint" multiplier="1.0" offset="-0.25"/>
    <parent link="f22_slot"/>
    <child link="f22"/>
    <axis xyz=" 0.70710678 -0.70710678  0.        "/>
    <origin xyz="0.0 0.0 0.0" rpy="0.0 -0.0 0.0"/>
  </joint>
  <joint name="f31_joint" type="revolute">
    <dynamics damping="100.0" friction="1.0"/>
    <limit effort="30.0" velocity="2.0" lower="-0.4" upper="0.25"/>
    <parent link="f31_base"/>
    <child link="f31"/>
    <axis xyz="-0.70710678 -0.70710678  0.        "/>
    <origin xyz="0.0 0.0 0.0" rpy="-0.25 -0.25 0.0"/>
  </joint>
  <joint name="f32_joint" type="revolute">
    <dynamics damping="100.0" friction="1.0"/>
    <limit effort="30.0" velocity="2.0" lower="-0.4" upper="0.0"/>
    <mimic joint="f31_joint" multiplier="1.0" offset="-0.25"/>
    <parent link="f32_slot"/>
    <child link="f32"/>
    <axis xyz="-0.70710678 -0.70710678  0.        "/>
    <origin xyz="0.0 0.0 0.0" rpy="0.0 0.0 0.0"/>
  </joint>
  <joint name="f11_base_joint" type="fixed">
    <parent link="palm"/>
    <child link="f11_base"/>
    <axis xyz="1. 0. 0."/>
    <origin xyz="0.05 0.0 0.0" rpy="0.0 0.0 0.0"/>
  </joint>
  <joint name="f12_slot_joint" type="fixed">
    <parent link="f11"/>
    <child link="f12_slot"/>
    <axis xyz="1. 0. 0."/>
    <origin xyz="0.0 0.0 0.08651739020966667" rpy="0.0 0.0 0.0"/>
  </joint>
  <joint name="f21_base_joint" type="fixed">
    <parent link="palm"/>
    <child link="f21_base"/>
    <axis xyz="1. 0. 0."/>
    <origin xyz="-0.025 -0.043301270189222 0.0" rpy="0.0 0.0 0.0"/>
  </joint>
  <joint name="f22_slot_joint" type="fixed">
    <parent link="f21"/>
    <child link="f22_slot"/>
    <axis xyz="1. 0. 0."/>
    <origin xyz="0.0 0.0 0.08651739020966667" rpy="0.0 0.0 0.0"/>
  </joint>
  <joint name="f31_base_joint" type="fixed">
    <parent link="palm"/>
    <child link="f31_base"/>
    <axis xyz="1. 0. 0."/>
    <origin xyz="-0.025 0.043301270189222 0.0" rpy="0.0 0.0 0.0"/>
  </joint>
  <joint name="f32_slot_joint" type="fixed">
    <parent link="f31"/>
    <child link="f32_slot"/>
    <axis xyz="1. 0. 0."/>
    <origin xyz="0.0 0.0 0.08651739020966667" rpy="0.0 0.0 0.0"/>
  </joint>
  <joint name="f13_slot_joint" type="fixed">
    <parent link="f12"/>
    <child link="f13_slot"/>
    <axis xyz="1. 0. 0."/>
    <origin xyz="0.0 0.0 0.07351870041463854" rpy="0.0 0.0 0.0"/>
  </joint>
  <joint name="f23_slot_joint" type="fixed">
    <parent link="f22"/>
    <child link="f23_slot"/>
    <axis xyz="1. 0. 0."/>
    <origin xyz="0.0 0.0 0.07351870041463854" rpy="0.0 0.0 0.0"/>
  </joint>
  <joint name="f33_slot_joint" type="fixed">
    <parent link="f32"/>
    <child link="f33_slot"/>
    <axis xyz="1. 0. 0."/>
    <origin xyz="0.0 0.0 0.07351870041463854" rpy="0.0 0.0 0.0"/>
  </joint>
  <material name="LightGrey">
    <color rgba="0.7 0.7 0.7 1. "/>
  </material>
  <material name="blue">
    <color rgba="0.  0.  0.8 1. "/>
  </material>
  <material name="green">
    <color rgba="0. 1. 0. 1."/>
  </material>
</robot>
